Workbook

Sheet dB題庫
A1: 題號 | B1: 題目 | C1: A | D1: B | E1: C | F1: D | G1: 答案 | H1: 題解
A2: 1 | B2: 當空氣密度增加時，對飛機升力的影響為何者 | C2: 升力增加。 | D2: 升力降低。 | E2: 升力不變。 | F2: 升力有時增加有時降低。 | G2: A | H2: 根據空氣動力學升力公式 L = 1/2‧rho‧V 平方‧S‧C_l，升力與空氣密度 (rho) 成正比。當空氣密度增加時，氣流產生的動壓隨之增大，使得機翼上下表面的壓力差(即升力)增加。這也是為何飛機在低海拔、低溫(空氣密度大)的環境中起飛性能較佳的原因。 當空氣密度增加時，飛機的升力會增加。這是因為升力與空氣密度成正比。根據空氣動力學的升力方程式 L = 1/2‧rho‧V 平方‧S‧C_l，當空氣密度（rho）上升時，機翼所能產生的氣動升力也會隨之提升。
A3: 2 | B3: 下列何者非影響空氣密度之因素 | C3: 高度。 | D3: 溫度。 | E3: 濕度。 | F3: 應力。 | G3: D | H3: 影響空氣密度的三大核心氣象因素為：高度(高度越高，氣壓越低，氣體分子越少，密度越小)、溫度(溫度越高，分子間距變大，密度越小)及濕度(水蒸氣分子比氮氣與氧氣輕，濕度越高則空氣越輕，密度越小)。而『應力』屬於固體力學範疇，並非改變大氣密度的氣象因子。
A4: 3 | B4: 當空氣中分子較少且稀薄，表示其密度高度為何 | C4: 越高。 | D4: 越低。 | E4: 可能高也可能低。 | F4: 無法判斷。 | G4: A | H4: 『密度高度』(Density Altitude)是指標準大氣中與特定空氣密度相對應的高度。當空氣分子較少、空氣稀薄(密度低)時，其表現與標準大氣中較高海拔處的空氣特性相符，因此對應的『密度高度越高』。高密度高度會顯著降低航空器的引擎出力與機翼升力效率。 當空氣中分子較少且稀薄時，代表其密度高度（Density Altitude）越高。「密度高度」是指將當下大氣狀態（包含高度、溫度、濕度與氣壓等）換算為標準大氣壓下所對應的等效高度。高密度高度代表空氣分子稀疏，因此飛機或無人機在此環境下的空氣動力性能會變差。
A5: 4 | B5: 當空氣中分子較多且濃厚，表示其密度高度為何 | C5: 越高。 | D5: 越低。 | E5: 可能高也可能低。 | F5: 無法判斷。 | G5: B | H5: 空氣分子較多且濃厚意味著空氣密度高。高密度的空氣與標準大氣中低海拔處的空氣密度相符，因此其『密度高度越低』。低密度高度是飛行的理想環境，能提供無人機極佳的發動機效率與升力性能。
A6: 5 | B6: 高密度高度之環境比較不會出現於下列何處 | C6: 低海拔處。 | D6: 高溫處。 | E6: 非常潮濕之處。 | F6: 低大氣壓力之處。 | G6: A | H6: 高密度高度意指空氣稀薄的環境。高溫、高濕度、低大氣壓力均會導致空氣密度降低(即拉高密度高度)。相對地，低海拔處通常氣壓較高、空氣較為濃厚，屬於低密度高度環境，因此『高密度高度』比較不會出現在低海拔處。
A7: 6 | B7: 低密度高度之環境比較不會出現於下列何處 | C7: 大氣壓力極高之處。 | D7: 低海拔處。 | E7: 乾燥處。 | F7: 高溫處。 | G7: D | H7: 低密度高度意指空氣密集的良好飛行環境。高大氣壓力、低海拔以及乾燥空氣(水氣少)皆會使空氣密度增加，進而降低密度高度。而『高溫處』會使空氣分子膨脹、密度下降，表現出高密度高度特徵，因此低密度高度環境絕對不會出現在高溫處。
A8: 7 | B8: 空氣可藉由外界的作功達到下列哪種效果 | C8: 加工成形。 | D8: 染色。 | E8: 壓縮及膨脹。 | F8: 以上皆主。 | G8: C | H8: 大氣是由氣體分子所組成的流體，具備顯著的可壓縮性。當外界對空氣施加力(做功)時(如氣流通過收縮管道或上升受壓改變)，空氣體積會隨之發生『壓縮』或『膨脹』，進而改變其溫度與壓力，這是熱力學與航空氣象的核心原理。
A9: 8 | B9: 於固定空氣體積下，升溫時該體積空氣密度減少，降溫時該體積空氣密度為下列何種變化 | C9: 增加。 | D9: 減少。 | E9: 不變。 | F9: 有時增加有時減少。 | G9: A | H9: 根據氣體狀態方程($P = \rho R T$)，在固定體積或恆定壓力下，氣體的密度($\rho$)與絕對溫度($T$)成反比。當空氣溫度下降(降溫)時，氣體分子的熱運動減弱、彼此靠攏，導致單位體積內的分子數量增加，即空氣密度『增加』。
A10: 9 | B10: 對流層裡，溫度及壓力均隨高度增加而有下列何種變化 | C10: 降低。 | D10: 增加。 | E10: 不變。 | F10: 有時增加有時降低。 | G10: A | H10: 在地球大氣的對流層中，大氣的主要熱源來自於地表吸收太陽輻射後的長波長再輻射，且上方空氣柱變短使壓力減小。因此，隨著海拔高度的增加，氣溫(平均每上升1,000英呎下降2°C)與大氣壓力均呈現持續『降低』的現象。
A11: 10 | B11: 下列有關大氣壓力量測之敘述，何者錯誤 | C11: 國際標準大氣(International Standard Atmosphere,ISA)為各國公認之參考校正基準。 | D11: 海平面大氣壓力為29.92英吋汞柱(inHg)。 | E11: 一標準大氣壓力等於1017.2毫巴值。 | F11: 每上升1,000英呎，氣壓值減少約1英吋汞柱。 | G11: C | H11: 在國際標準大氣(ISA)環境中，海平面標準大氣壓力定義為 29.92 英吋汞柱(inHg)，等值換算應為 1013.25 毫巴(mb/hPa)，而非 1017.2 毫巴。因此選項 (C) 敘述錯誤，為本題之正確答案。
A12: 11 | B12: 標準一大氣壓的29.92吋汞柱換算成毫巴值為下列哪個數值 | C12: 10.132。 | D12: 101.32。 | E12: 1013.2。 | F12: 10132。 | G12: C | H12: 大氣壓力的單位換算中，標準海平面氣壓等於 29.92 英吋汞柱，國際單位制(SI)對應數值約為 1013.25 毫巴(millibar，縮寫為 mb)或百帕(hPa)。故最適選項為 (C) 1013.2。
... A83: 82 | B83: 終端機場天氣觀測報中,盛行天氣現象包括下列哪個項目 | C83: 風向風速。 | D83: 能見度。 | E83: 天氣狀況及雲組。 | F83: 以上皆是。 | G83: D | H83: 一分完整的終端機場天氣觀測報告(METAR)中，為了能全面反映機場當前的盛行氣象條件，所包含的觀測核心項目包括了風向與風速、地面盛行能見度、當前的特殊天氣狀況(如雨、霧)以及雲組(雲量與雲高)，因此選項 (D) 以上皆是正確答案。

Sheet 【讀給你聽】
A1: 題號 | B1: 題目 | C1: 普通操作證學科測驗題庫 | D1: A | E1: B | F1: C | G1: D | H1: 答案 | I1: 題解
C2: 第三章：氣象
C3: 115年7月22日版
A5: =dB題庫!A2 -> 1 | B5: =dB題庫!B2 -> 當空氣密度增加時，對飛機升力的影響為何者 | C5: =A5&"."&B5 -> 1.當空氣密度增加時，對飛機升力的影響為何者 | D5: =dB題庫!C2 -> 升力增加。 | E5: =dB題庫!D2 -> 升力降低。 | F5: =dB題庫!E2 -> 升力不變。 | G5: =dB題庫!F2 -> 升力有時增加有時降低。 | H5: =dB題庫!G2 -> A | I5: =dB題庫!H2 -> 根據空氣動力學升力公式 L = 1/2‧rho‧V 平方‧S‧C_l，升力與空氣密度 (rho) 成正比。當空氣密度增加時，氣流產生的動壓隨之增大，使得機翼上下表面的壓力差(即升力)增加。這也是為何飛機在低海拔、低溫(空氣密度大)的環境中起飛性能較佳的原因。 當空氣密度增加時，飛機的升力會增加。這是因為升力與空氣密度成正比。根據空氣動力學的升力方程式 L = 1/2‧rho‧V 平方‧S‧C_l，當空氣密度（rho）上升時，機翼所能產生的氣動升力也會隨之提升。
C6: ="(A.)"&D5 -> (A.)升力增加。
C7: ="(B.)"&E5 -> (B.)升力降低。
C8: ="(C.)"&F5 -> (C.)升力不變。
C9: ="(D.)"&G5 -> (D.)升力有時增加有時降低。
C10: ="答案是： "&IF(H5="A",C6,IF(H5="B",C7,IF(H5="C",C8,IF(H5=("D"),C9,"XXXX")))) -> 答案是： (A.)升力增加。
C11: ="說明："&I5 -> 說明：根據空氣動力學升力公式 L = 1/2‧rho‧V 平方‧S‧C_l，升力與空氣密度 (rho) 成正比。當空氣密度增加時，氣流產生的動壓隨之增大，使得機翼上下表面的壓力差(即升力)增加。這也是為何飛機在低海拔、低溫(空氣密度大)的環境中起飛性能較佳的原因。 當空氣密度增加時，飛機的升力會增加。這是因為升力與空氣密度成正比。根據空氣動力學的升力方程式 L = 1/2‧rho‧V 平方‧S‧C_l，當空氣密度（rho）上升時，機翼所能產生的氣動升力也會隨之提升。
A12: =dB題庫!A3 -> 2 | B12: =dB題庫!B3 -> 下列何者非影響空氣密度之因素 | C12: =A12&"."&B12 -> 2.下列何者非影響空氣密度之因素 | D12: =dB題庫!C3 -> 高度。 | E12: =dB題庫!D3 -> 溫度。 | F12: =dB題庫!E3 -> 濕度。 | G12: =dB題庫!F3 -> 應力。 | H12: =dB題庫!G3 -> D | I12: =dB題庫!H3 -> 影響空氣密度的三大核心氣象因素為：高度(高度越高，氣壓越低，氣體分子越少，密度越小)、溫度(溫度越高，分子間距變大，密度越小)及濕度(水蒸氣分子比氮氣與氧氣輕，濕度越高則空氣越輕，密度越小)。而『應力』屬於固體力學範疇，並非改變大氣密度的氣象因子。
C13: ="(A.)"&D12 -> (A.)高度。
C14: ="(B.)"&E12 -> (B.)溫度。
C15: ="(C.)"&F12 -> (C.)濕度。
C16: ="(D.)"&G12 -> (D.)應力。
C17: ="答案是： "&IF(H12="A",C13,IF(H12="B",C14,IF(H12="C",C15,IF(H12=("D"),C16,"XXXX")))) -> 答案是： (D.)應力。
C18: ="說明："&I12 -> 說明：影響空氣密度的三大核心氣象因素為：高度(高度越高，氣壓越低，氣體分子越少，密度越小)、溫度(溫度越高，分子間距變大，密度越小)及濕度(水蒸氣分子比氮氣與氧氣輕，濕度越高則空氣越輕，密度越小)。而『應力』屬於固體力學範疇，並非改變大氣密度的氣象因子。
A19: =dB題庫!A4 -> 3 | B19: =dB題庫!B4 -> 當空氣中分子較少且稀薄，表示其密度高度為何 | C19: =A19&"."&B19 -> 3.當空氣中分子較少且稀薄，表示其密度高度為何 | D19: =dB題庫!C4 -> 越高。 | E19: =dB題庫!D4 -> 越低。 | F19: =dB題庫!E4 -> 可能高也可能低。 | G19: =dB題庫!F4 -> 無法判斷。 | H19: =dB題庫!G4 -> A | I19: =dB題庫!H4 -> 『密度高度』(Density Altitude)是指標準大氣中與特定空氣密度相對應的高度。當空氣分子較少、空氣稀薄(密度低)時，其表現與標準大氣中較高海拔處的空氣特性相符，因此對應的『密度高度越高』。高密度高度會顯著降低航空器的引擎出力與機翼升力效率。 當空氣中分子較少且稀薄時，代表其密度高度（Density Altitude）越高。「密度高度」是指將當下大氣狀態（包含高度、溫度、濕度與氣壓等）換算為標準大氣壓下所對應的等效高度。高密度高度代表空氣分子稀疏，因此飛機或無人機在此環境下的空氣動力性能會變差。
C20: ="(A.)"&D19 -> (A.)越高。
C21: ="(B.)"&E19 -> (B.)越低。
C22: ="(C.)"&F19 -> (C.)可能高也可能低。
C23: ="(D.)"&G19 -> (D.)無法判斷。
C24: ="答案是： "&IF(H19="A",C20,IF(H19="B",C21,IF(H19="C",C22,IF(H19=("D"),C23,"XXXX")))) -> 答案是： (A.)越高。
C25: ="說明："&I19 -> 說明：『密度高度』(Density Altitude)是指標準大氣中與特定空氣密度相對應的高度。當空氣分子較少、空氣稀薄(密度低)時，其表現與標準大氣中較高海拔處的空氣特性相符，因此對應的『密度高度越高』。高密度高度會顯著降低航空器的引擎出力與機翼升力效率。 當空氣中分子較少且稀薄時，代表其密度高度（Density Altitude）越高。「密度高度」是指將當下大氣狀態（包含高度、溫度、濕度與氣壓等）換算為標準大氣壓下所對應的等效高度。高密度高度代表空氣分子稀疏，因此飛機或無人機在此環境下的空氣動力性能會變差。
A26: =dB題庫!A5 -> 4 | B26: =dB題庫!B5 -> 當空氣中分子較多且濃厚，表示其密度高度為何 | C26: =A26&"."&B26 -> 4.當空氣中分子較多且濃厚，表示其密度高度為何 | D26: =dB題庫!C5 -> 越高。 | E26: =dB題庫!D5 -> 越低。 | F26: =dB題庫!E5 -> 可能高也可能低。 | G26: =dB題庫!F5 -> 無法判斷。 | H26: =dB題庫!G5 -> B | I26: =dB題庫!H5 -> 空氣分子較多且濃厚意味著空氣密度高。高密度的空氣與標準大氣中低海拔處的空氣密度相符，因此其『密度高度越低』。低密度高度是飛行的理想環境，能提供無人機極佳的發動機效率與升力性能。
C27: ="(A.)"&D26 -> (A.)越高。
C28: ="(B.)"&E26 -> (B.)越低。
C29: ="(C.)"&F26 -> (C.)可能高也可能低。
C30: ="(D.)"&G26 -> (D.)無法判斷。
C31: ="答案是： "&IF(H26="A",C27,IF(H26="B",C28,IF(H26="C",C29,IF(H26=("D"),C30,"XXXX")))) -> 答案是： (B.)越低。
C32: ="說明："&I26 -> 說明：空氣分子較多且濃厚意味著空氣密度高。高密度的空氣與標準大氣中低海拔處的空氣密度相符，因此其『密度高度越低』。低密度高度是飛行的理想環境，能提供無人機極佳的發動機效率與升力性能。
A33: =dB題庫!A6 -> 5 | B33: =dB題庫!B6 -> 高密度高度之環境比較不會出現於下列何處 | C33: =A33&"."&B33 -> 5.高密度高度之環境比較不會出現於下列何處 | D33: =dB題庫!C6 -> 低海拔處。 | E33: =dB題庫!D6 -> 高溫處。 | F33: =dB題庫!E6 -> 非常潮濕之處。 | G33: =dB題庫!F6 -> 低大氣壓力之處。 | H33: =dB題庫!G6 -> A | I33: =dB題庫!H6 -> 高密度高度意指空氣稀薄的環境。高溫、高濕度、低大氣壓力均會導致空氣密度降低(即拉高密度高度)。相對地，低海拔處通常氣壓較高、空氣較為濃厚，屬於低密度高度環境，因此『高密度高度』比較不會出現在低海拔處。
C34: ="(A.)"&D33 -> (A.)低海拔處。
C35: ="(B.)"&E33 -> (B.)高溫處。
C36: ="(C.)"&F33 -> (C.)非常潮濕之處。
C37: ="(D.)"&G33 -> (D.)低大氣壓力之處。
C38: ="答案是： "&IF(H33="A",C34,IF(H33="B",C35,IF(H33="C",C36,IF(H33=("D"),C37,"XXXX")))) -> 答案是： (A.)低海拔處。
C39: ="說明："&I33 -> 說明：高密度高度意指空氣稀薄的環境。高溫、高濕度、低大氣壓力均會導致空氣密度降低(即拉高密度高度)。相對地，低海拔處通常氣壓較高、空氣較為濃厚，屬於低密度高度環境，因此『高密度高度』比較不會出現在低海拔處。
A40: =dB題庫!A7 -> 6 | B40: =dB題庫!B7 -> 低密度高度之環境比較不會出現於下列何處 | C40: =A40&"."&B40 -> 6.低密度高度之環境比較不會出現於下列何處 | D40: =dB題庫!C7 -> 大氣壓力極高之處。 | E40: =dB題庫!D7 -> 低海拔處。 | F40: =dB題庫!E7 -> 乾燥處。 | G40: =dB題庫!F7 -> 高溫處。 | H40: =dB題庫!G7 -> D | I40: =dB題庫!H7 -> 低密度高度意指空氣密集的良好飛行環境。高大氣壓力、低海拔以及乾燥空氣(水氣少)皆會使空氣密度增加，進而降低密度高度。而『高溫處』會使空氣分子膨脹、密度下降，表現出高密度高度特徵，因此低密度高度環境絕對不會出現在高溫處。
C41: ="(A.)"&D40 -> (A.)大氣壓力極高之處。
...

Sheet Steps
B2: Question
B3: A
B4: B
B5: C
B6: D
B7: "="答案是： "&IF(G2="A",1,IF(G2="B",2,IF(G2="C",3,IF(G2=("D"),4,"XXXX"))))"
B8: Note
